Workbook

Sheet README
A1: Extraction review – R1 vs R2 (pilot, 5 studies)
A2: Inputs: R1 = r1_retrieval_1.ods (venue_type re-reviewed via Scimago) · R2 = r2_extraction_v4.ods (schema 0.9.0). Identical structure; meta sheets differ only in boolean encoding (no content differences).
A4: Sheets
A5: Summary – open/resolved counts per study and field group; per-field raw agreement (live formulas).
A6: Comparison – one row per value field where R1 ≠ R2; the Field column carries the schema annotation (type, definition, allowed values) from the extraction-file header notes. Resolve here: fill the yellow columns.
A7: Metrics_Comparison – reported_metrics aligned by best match (name+value similarity); decide which entries to keep.
A8: Reasoning_Only – reasoning/rationale texts that differ although the value agrees (or is listed in Comparison). Reference only; no decision required.
A9: Review_Version – consensus record in the original wide layout. Agreed values are final (green); disagreements pull the consensus from Comparison automatically and show ⚠ UNRESOLVED until Status = Resolved (red).
A10: R1_studies / R2_studies / R1_metrics / R2_metrics – unmodified source data.
A12: Normalisation before comparing
A13: Booleans TRUE/1 and FALSE/0 treated as equal; multi-select fields compared as sets (order ignored); whitespace collapsed. Case-only differences listed as Low.
A15: Priority
... A27: Blue = re-coded under schema v0.10.0 (repeated_runs free text; efficiency_metrics_reported yes/partially/no; data_available full/partial/none).

Sheet Summary
A1: Disagreements per study
A2: Study | B2: High | C2: Medium | D2: Low | E2: Total | F2: Resolved | G2: Escalated R3 | H2: Open | I2: % resolved | J2: Metrics: identical | K2: Metrics: differs | L2: Metrics: only R1 | M2: Metrics: only R2
A3: S1 – Schmitt et al. (2026) | B3: =COUNTIFS(Comparison!$B$2:$B$164,$A3,Comparison!$F$2:$F$164,"High") -> 13 | C3: =COUNTIFS(Comparison!$B$2:$B$164,$A3,Comparison!$F$2:$F$164,"Medium") -> 11 | D3: =COUNTIFS(Comparison!$B$2:$B$164,$A3,Comparison!$F$2:$F$164,"Low") -> 1 | E3: =SUM(B3:D3) -> 25 | F3: =COUNTIFS(Comparison!$B$2:$B$164,$A3,Comparison!$N$2:$N$164,"Resolved") -> 25 | G3: =COUNTIFS(Comparison!$B$2:$B$164,$A3,Comparison!$N$2:$N$164,"Escalate-R3") -> 0 | H3: =E3-F3 -> 0 | I3: =IF(E3=0,1,F3/E3) -> 1 | J3: =COUNTIFS(Metrics_Comparison!$A$2:$A$80,$A3,Metrics_Comparison!$B$2:$B$80,"Identical") -> 0 | K3: =COUNTIFS(Metrics_Comparison!$A$2:$A$80,$A3,Metrics_Comparison!$B$2:$B$80,"Matched – differs") -> 4 | L3: =COUNTIFS(Metrics_Comparison!$A$2:$A$80,$A3,Metrics_Comparison!$B$2:$B$80,"Only R1") -> 11 | M3: =COUNTIFS(Metrics_Comparison!$A$2:$A$80,$A3,Metrics_Comparison!$B$2:$B$80,"Only R2") -> 8
A4: S2 – Werheid et al. (2025) | B4: =COUNTIFS(Comparison!$B$2:$B$164,$A4,Comparison!$F$2:$F$164,"High") -> 14 | C4: =COUNTIFS(Comparison!$B$2:$B$164,$A4,Comparison!$F$2:$F$164,"Medium") -> 17 | D4: =COUNTIFS(Comparison!$B$2:$B$164,$A4,Comparison!$F$2:$F$164,"Low") -> 0 | E4: =SUM(B4:D4) -> 31 | F4: =COUNTIFS(Comparison!$B$2:$B$164,$A4,Comparison!$N$2:$N$164,"Resolved") -> 31 | G4: =COUNTIFS(Comparison!$B$2:$B$164,$A4,Comparison!$N$2:$N$164,"Escalate-R3") -> 0 | H4: =E4-F4 -> 0 | I4: =IF(E4=0,1,F4/E4) -> 1 | J4: =COUNTIFS(Metrics_Comparison!$A$2:$A$80,$A4,Metrics_Comparison!$B$2:$B$80,"Identical") -> 0 | K4: =COUNTIFS(Metrics_Comparison!$A$2:$A$80,$A4,Metrics_Comparison!$B$2:$B$80,"Matched – differs") -> 4 | L4: =COUNTIFS(Metrics_Comparison!$A$2:$A$80,$A4,Metrics_Comparison!$B$2:$B$80,"Only R1") -> 0 | M4: =COUNTIFS(Metrics_Comparison!$A$2:$A$80,$A4,Metrics_Comparison!$B$2:$B$80,"Only R2") -> 0
A5: S3 – Hu et al. (2026) | B5: =COUNTIFS(Comparison!$B$2:$B$164,$A5,Comparison!$F$2:$F$164,"High") -> 22 | C5: =COUNTIFS(Comparison!$B$2:$B$164,$A5,Comparison!$F$2:$F$164,"Medium") -> 17 | D5: =COUNTIFS(Comparison!$B$2:$B$164,$A5,Comparison!$F$2:$F$164,"Low") -> 1 | E5: =SUM(B5:D5) -> 40 | F5: =COUNTIFS(Comparison!$B$2:$B$164,$A5,Comparison!$N$2:$N$164,"Resolved") -> 40 | G5: =COUNTIFS(Comparison!$B$2:$B$164,$A5,Comparison!$N$2:$N$164,"Escalate-R3") -> 0 | H5: =E5-F5 -> 0 | I5: =IF(E5=0,1,F5/E5) -> 1 | J5: =COUNTIFS(Metrics_Comparison!$A$2:$A$80,$A5,Metrics_Comparison!$B$2:$B$80,"Identical") -> 0 | K5: =COUNTIFS(Metrics_Comparison!$A$2:$A$80,$A5,Metrics_Comparison!$B$2:$B$80,"Matched – differs") -> 5 | L5: =COUNTIFS(Metrics_Comparison!$A$2:$A$80,$A5,Metrics_Comparison!$B$2:$B$80,"Only R1") -> 10 | M5: =COUNTIFS(Metrics_Comparison!$A$2:$A$80,$A5,Metrics_Comparison!$B$2:$B$80,"Only R2") -> 4
A6: S4 – Gao et al. (2026) | B6: =COUNTIFS(Comparison!$B$2:$B$164,$A6,Comparison!$F$2:$F$164,"High") -> 17 | C6: =COUNTIFS(Comparison!$B$2:$B$164,$A6,Comparison!$F$2:$F$164,"Medium") -> 17 | D6: =COUNTIFS(Comparison!$B$2:$B$164,$A6,Comparison!$F$2:$F$164,"Low") -> 0 | E6: =SUM(B6:D6) -> 34 | F6: =COUNTIFS(Comparison!$B$2:$B$164,$A6,Comparison!$N$2:$N$164,"Resolved") -> 34 | G6: =COUNTIFS(Comparison!$B$2:$B$164,$A6,Comparison!$N$2:$N$164,"Escalate-R3") -> 0 | H6: =E6-F6 -> 0 | I6: =IF(E6=0,1,F6/E6) -> 1 | J6: =COUNTIFS(Metrics_Comparison!$A$2:$A$80,$A6,Metrics_Comparison!$B$2:$B$80,"Identical") -> 0 | K6: =COUNTIFS(Metrics_Comparison!$A$2:$A$80,$A6,Metrics_Comparison!$B$2:$B$80,"Matched – differs") -> 13 | L6: =COUNTIFS(Metrics_Comparison!$A$2:$A$80,$A6,Metrics_Comparison!$B$2:$B$80,"Only R1") -> 16 | M6: =COUNTIFS(Metrics_Comparison!$A$2:$A$80,$A6,Metrics_Comparison!$B$2:$B$80,"Only R2") -> 0
A7: S5 – Simchi-Levi et al. (2025) | B7: =COUNTIFS(Comparison!$B$2:$B$164,$A7,Comparison!$F$2:$F$164,"High") -> 16 | C7: =COUNTIFS(Comparison!$B$2:$B$164,$A7,Comparison!$F$2:$F$164,"Medium") -> 17 | D7: =COUNTIFS(Comparison!$B$2:$B$164,$A7,Comparison!$F$2:$F$164,"Low") -> 0 | E7: =SUM(B7:D7) -> 33 | F7: =COUNTIFS(Comparison!$B$2:$B$164,$A7,Comparison!$N$2:$N$164,"Resolved") -> 33 | G7: =COUNTIFS(Comparison!$B$2:$B$164,$A7,Comparison!$N$2:$N$164,"Escalate-R3") -> 0 | H7: =E7-F7 -> 0 | I7: =IF(E7=0,1,F7/E7) -> 1 | J7: =COUNTIFS(Metrics_Comparison!$A$2:$A$80,$A7,Metrics_Comparison!$B$2:$B$80,"Identical") -> 0 | K7: =COUNTIFS(Metrics_Comparison!$A$2:$A$80,$A7,Metrics_Comparison!$B$2:$B$80,"Matched – differs") -> 3 | L7: =COUNTIFS(Metrics_Comparison!$A$2:$A$80,$A7,Metrics_Comparison!$B$2:$B$80,"Only R1") -> 1 | M7: =COUNTIFS(Metrics_Comparison!$A$2:$A$80,$A7,Metrics_Comparison!$B$2:$B$80,"Only R2") -> 0
A8: Total | B8: =SUM(B3:B7) -> 82 | C8: =SUM(C3:C7) -> 79 | D8: =SUM(D3:D7) -> 2 | E8: =SUM(E3:E7) -> 163 | F8: =SUM(F3:F7) -> 163 | G8: =SUM(G3:G7) -> 0 | H8: =SUM(H3:H7) -> 0 | I8: =IF(E8=0,1,F8/E8) -> 1 | J8: =SUM(J3:J7) -> 0 | K8: =SUM(K3:K7) -> 29 | L8: =SUM(L3:L7) -> 38 | M8: =SUM(M3:M7) -> 12
A10: Disagreements per field group
A11: Field group | B11: High | C11: Medium | D11: Low | E11: Total | F11: Resolved | G11: Open
A12: study | B12: =COUNTIFS(Comparison!$C$2:$C$164,$A12,Comparison!$F$2:$F$164,"High") -> 0 | C12: =COUNTIFS(Comparison!$C$2:$C$164,$A12,Comparison!$F$2:$F$164,"Medium") -> 1 | D12: =COUNTIFS(Comparison!$C$2:$C$164,$A12,Comparison!$F$2:$F$164,"Low") -> 0 | E12: =SUM(B12:D12) -> 1 | F12: =COUNTIFS(Comparison!$C$2:$C$164,$A12,Comparison!$N$2:$N$164,"Resolved") -> 1 | G12: =E12-F12 -> 0
A13: bibliographic_metadata | B13: =COUNTIFS(Comparison!$C$2:$C$164,$A13,Comparison!$F$2:$F$164,"High") -> 0 | C13: =COUNTIFS(Comparison!$C$2:$C$164,$A13,Comparison!$F$2:$F$164,"Medium") -> 7 | D13: =COUNTIFS(Comparison!$C$2:$C$164,$A13,Comparison!$F$2:$F$164,"Low") -> 0 | E13: =SUM(B13:D13) -> 7 | F13: =COUNTIFS(Comparison!$C$2:$C$164,$A13,Comparison!$N$2:$N$164,"Resolved") -> 7 | G13: =E13-F13 -> 0
A14: study_characterization | B14: =COUNTIFS(Comparison!$C$2:$C$164,$A14,Comparison!$F$2:$F$164,"High") -> 1 | C14: =COUNTIFS(Comparison!$C$2:$C$164,$A14,Comparison!$F$2:$F$164,"Medium") -> 9 | D14: =COUNTIFS(Comparison!$C$2:$C$164,$A14,Comparison!$F$2:$F$164,"Low") -> 2 | E14: =SUM(B14:D14) -> 12 | F14: =COUNTIFS(Comparison!$C$2:$C$164,$A14,Comparison!$N$2:$N$164,"Resolved") -> 12 | G14: =E14-F14 -> 0
A15: strategic_planning_scope | B15: =COUNTIFS(Comparison!$C$2:$C$164,$A15,Comparison!$F$2:$F$164,"High") -> 16 | C15: =COUNTIFS(Comparison!$C$2:$C$164,$A15,Comparison!$F$2:$F$164,"Medium") -> 8 | D15: =COUNTIFS(Comparison!$C$2:$C$164,$A15,Comparison!$F$2:$F$164,"Low") -> 0 | E15: =SUM(B15:D15) -> 24 | F15: =COUNTIFS(Comparison!$C$2:$C$164,$A15,Comparison!$N$2:$N$164,"Resolved") -> 24 | G15: =E15-F15 -> 0
A16: llm_intervention | B16: =COUNTIFS(Comparison!$C$2:$C$164,$A16,Comparison!$F$2:$F$164,"High") -> 17 | C16: =COUNTIFS(Comparison!$C$2:$C$164,$A16,Comparison!$F$2:$F$164,"Medium") -> 16 | D16: =COUNTIFS(Comparison!$C$2:$C$164,$A16,Comparison!$F$2:$F$164,"Low") -> 0 | E16: =SUM(B16:D16) -> 33 | F16: =COUNTIFS(Comparison!$C$2:$C$164,$A16,Comparison!$N$2:$N$164,"Resolved") -> 33 | G16: =E16-F16 -> 0
A17: or_substrate | B17: =COUNTIFS(Comparison!$C$2:$C$164,$A17,Comparison!$F$2:$F$164,"High") -> 9 | C17: =COUNTIFS(Comparison!$C$2:$C$164,$A17,Comparison!$F$2:$F$164,"Medium") -> 4 | D17: =COUNTIFS(Comparison!$C$2:$C$164,$A17,Comparison!$F$2:$F$164,"Low") -> 0 | E17: =SUM(B17:D17) -> 13 | F17: =COUNTIFS(Comparison!$C$2:$C$164,$A17,Comparison!$N$2:$N$164,"Resolved") -> 13 | G17: =E17-F17 -> 0
A18: evaluation_and_outcomes | B18: =COUNTIFS(Comparison!$C$2:$C$164,$A18,Comparison!$F$2:$F$164,"High") -> 8 | C18: =COUNTIFS(Comparison!$C$2:$C$164,$A18,Comparison!$F$2:$F$164,"Medium") -> 19 | D18: =COUNTIFS(Comparison!$C$2:$C$164,$A18,Comparison!$F$2:$F$164,"Low") -> 0 | E18: =SUM(B18:D18) -> 27 | F18: =COUNTIFS(Comparison!$C$2:$C$164,$A18,Comparison!$N$2:$N$164,"Resolved") -> 27 | G18: =E18-F18 -> 0
A19: record | B19: =COUNTIFS(Comparison!$C$2:$C$164,$A19,Comparison!$F$2:$F$164,"High") -> 4 | C19: =COUNTIFS(Comparison!$C$2:$C$164,$A19,Comparison!$F$2:$F$164,"Medium") -> 0 | D19: =COUNTIFS(Comparison!$C$2:$C$164,$A19,Comparison!$F$2:$F$164,"Low") -> 0 | E19: =SUM(B19:D19) -> 4 | F19: =COUNTIFS(Comparison!$C$2:$C$164,$A19,Comparison!$N$2:$N$164,"Resolved") -> 4 | G19: =E19-F19 -> 0
A20: retrieval_traceability | B20: =COUNTIFS(Comparison!$C$2:$C$164,$A20,Comparison!$F$2:$F$164,"High") -> 0 | C20: =COUNTIFS(Comparison!$C$2:$C$164,$A20,Comparison!$F$2:$F$164,"Medium") -> 0 | D20: =COUNTIFS(Comparison!$C$2:$C$164,$A20,Comparison!$F$2:$F$164,"Low") -> 0 | E20: =SUM(B20:D20) -> 0 | F20: =COUNTIFS(Comparison!$C$2:$C$164,$A20,Comparison!$N$2:$N$164,"Resolved") -> 0 | G20: =E20-F20 -> 0
A21: gap_indicators | B21: =COUNTIFS(Comparison!$C$2:$C$164,$A21,Comparison!$F$2:$F$164,"High") -> 15 | C21: =COUNTIFS(Comparison!$C$2:$C$164,$A21,Comparison!$F$2:$F$164,"Medium") -> 15 | D21: =COUNTIFS(Comparison!$C$2:$C$164,$A21,Comparison!$F$2:$F$164,"Low") -> 0 | E21: =SUM(B21:D21) -> 30 | F21: =COUNTIFS(Comparison!$C$2:$C$164,$A21,Comparison!$N$2:$N$164,"Resolved") -> 30 | G21: =E21-F21 -> 0
A22: quality_appraisal | B22: =COUNTIFS(Comparison!$C$2:$C$164,$A22,Comparison!$F$2:$F$164,"High") -> 12 | C22: =COUNTIFS(Comparison!$C$2:$C$164,$A22,Comparison!$F$2:$F$164,"Medium") -> 0 | D22: =COUNTIFS(Comparison!$C$2:$C$164,$A22,Comparison!$F$2:$F$164,"Low") -> 0 | E22: =SUM(B22:D22) -> 12 | F22: =COUNTIFS(Comparison!$C$2:$C$164,$A22,Comparison!$N$2:$N$164,"Resolved") -> 12 | G22: =E22-F22 -> 0
A24: Raw agreement per field (n = 5 studies; value fields only)
A25: Field | B25: Type | C25: Studies disagreeing | D25: Raw agreement
A26: schema_version | B26: categorical | C26: =COUNTIFS(Comparison!$D$2:$D$164,$A26) -> 0 | D26: =1-C26/5 -> 1
A27: study_id | B27: categorical | C27: =COUNTIFS(Comparison!$D$2:$D$164,$A27) -> 0 | D27: =1-C27/5 -> 1
A28: bibliographic_metadata.doi | B28: free-text | C28: =COUNTIFS(Comparison!$D$2:$D$164,$A28) -> 0 | D28: =1-C28/5 -> 1
A29: bibliographic_metadata.title | B29: free-text | C29: =COUNTIFS(Comparison!$D$2:$D$164,$A29) -> 0 | D29: =1-C29/5 -> 1
A30: bibliographic_metadata.authors | B30: free-text | C30: =COUNTIFS(Comparison!$D$2:$D$164,$A30) -> 0 | D30: =1-C30/5 -> 1
A31: bibliographic_metadata.affiliations | B31: free-text | C31: =COUNTIFS(Comparison!$D$2:$D$164,$A31) -> 0 | D31: =1-C31/5 -> 1
A32: bibliographic_metadata.country | B32: free-text | C32: =COUNTIFS(Comparison!$D$2:$D$164,$A32) -> 0 | D32: =1-C32/5 -> 1
A33: bibliographic_metadata.year | B33: categorical | C33: =COUNTIFS(Comparison!$D$2:$D$164,$A33) -> 0 | D33: =1-C33/5 -> 1
A34: bibliographic_metadata.venue | B34: free-text | C34: =COUNTIFS(Comparison!$D$2:$D$164,$A34) -> 0 | D34: =1-C34/5 -> 1
A35: bibliographic_metadata.venue_type | B35: categorical | C35: =COUNTIFS(Comparison!$D$2:$D$164,$A35) -> 0 | D35: =1-C35/5 -> 1
A36: bibliographic_metadata.language | B36: categorical | C36: =COUNTIFS(Comparison!$D$2:$D$164,$A36) -> 0 | D36: =1-C36/5 -> 1
A37: bibliographic_metadata.funding_source | B37: free-text | C37: =COUNTIFS(Comparison!$D$2:$D$164,$A37) -> 0 | D37: =1-C37/5 -> 1
... A132: study_type_category | B132: categorical | C132: =COUNTIFS(Comparison!$D$2:$D$164,$A132) -> 0 | D132: =1-C132/5 -> 1

Sheet Comparison
A1: ID | B1: Study | C1: Field group | D1: Field | E1: Type | F1: Priority | G1: Difference | H1: R1 value | I1: R2 value | J1: R1 reasoning | K1: R2 reasoning | L1: Consensus value | M1: Consensus reasoning | N1: Status | O1: Resolution note | P1: Decided by | Q1: Triage (post-High) | R1: Triage rationale
A2: D001 | B2: S1 – Schmitt et al. (2026) | C2: study_characterization | D2: study_characterization.research_type Type: ResearchType Research type of the paper's contribution (Wieringa et al. 2006 facet). Lab/benchmark evaluation -> validation-research; evaluation in operational practice -> evaluation-research. Types: - validation-research: Novel technique evaluated in the lab / artificial setting (experiments, simulations, benchmarks, prototype on test cases), not yet used in practice - evaluation-research: Technique evaluated in practice (naturalistic setting: real organisation, real users, real data in operational use), incl. industrial case studies - solution-proposal: Novel or significantly extended technique, argued for with a small example or none; no thorough evaluation - philosophical-paper: New way of looking at the field: taxonomy, conceptual framework, research agenda - opinion-paper: Personal opinion on what is good or bad, not grounded in related work or method - experience-paper: Practitioner's account of what was done in practice and how it went | E2: categorical | F2: High | G2: Only R1: validation-research | Only R2: evaluation-research | H2: validation-research | I2: evaluation-research | J2: The paper proposes a novel end-to-end LLM-driven DES workflow (builder, inspector, visualizer, bottleneck, CPD, adaptor and evaluator agents) and evaluates it through 21 researcher-run experimental runs on two industrial production-line cases (Sec. 4.4, Sec. 5). Validation-research is chosen over evaluation-research because the workflow was not deployed in operational use by practitioners. The paper states: "Implementing the suggested changes in production fell outside the scope of this study" (Fig. 1 caption). Case B also used "a simplified mock-up event log", and the CPDs were fictitious (Sec. 4.2). Evaluation was through repeated experiments plus comparison against FACTS Analyzer models. Uncertainty (?): the cases come from a real company (Scania) and real MES data was used for Case A, so a reviewer could argue for evaluation-research under the 'industrial case studies' clause. | K2: The paper presents a novel LLM-driven workflow for discrete-event simulation (DES) and evaluates it using two real-world industrial case studies from a Swedish automotive manufacturer (Scania). The evaluation involves systematic analysis of 21 experimental runs, comparing generated models against commercial simulation software (FACTS Analyzer) with defined metrics (Throughput, WIP, SEC). This fits the definition of evaluation-research: 'Technique evaluated in practice (naturalistic setting: real organisation, real users, real data in operational use), incl. industrial case studies'. See Section 1 (Introduction), Section 4.2 (Use case and data collection), and Section 5 (Results). | L2: evaluation-research | M2: Case A is derived from real data, therefore industrial case study which fulfills the requirement under the clause “industrial case study” | N2: Resolved | Q2: Resolved by reviewers
A3: D002 | B3: S1 – Schmitt et al. (2026) | C3: study_characterization | D3: study_characterization.industry_sector Type: str Industry sector as reported. NR if absent. | E3: free-text | F3: Low | G3: Case/whitespace only | H3: Automotive manufacturing | I3: Automotive Manufacturing | J3: The cases come from "a large Swedish automotive manufacturer" (Sec. 1, Sec. 4.2). The affiliations name Scania CV AB. | K3: The paper explicitly states that the case studies are from 'a large Swedish automotive manufacturer' (identified as Scania CV AB in the author affiliations and abstract). The context is 'manufacturing industries' and 'production systems'. See Section 1 (Introduction) and Section 4.2 (Use case and data collection). | L3: Automotive manufacturing | N3: Resolved | P3: Triage | Q3: No discussion needed | R3: case only
A4: D003 | B4: S1 – Schmitt et al. (2026) | C4: study_characterization | D4: study_characterization.case_study_domain Type: str Case study domain as reported. NR if absent. | E4: free-text | F4: Medium | G4: Text differs (similarity 25%) | H4: Discrete-event simulation of production lines for capacity and energy-efficiency assessment (Case A: an automated machining line with 4 serial operations; Case B: an automated assembly line with 7 operations including parallel presses) | I4: Discrete-Event Simulation (DES) in Manufacturing | J4: Sec. 4.4 and Sec. 5 describe "an automated assembly line and an automated machining line". Sec. 5.3 describes Case A as four sequential operations. Sec. 5.4 describes Case B as seven machines with two parallel presses. The KPIs were TH, WIP and SEC (Sec. 4.2). | K4: The core domain is the automation of Discrete-Event Simulation (DES) modeling for manufacturing systems. The specific application areas are capacity analysis, energy efficiency assessment, and bottleneck identification in production lines (machining and assembly). See Abstract and Section 2.2 (Manufacturing system simulation). | L4: Discrete-event simulation of production lines for capacity and energy-efficiency assessment (Case A: an automated machining line with 4 serial operations; Case B: an automated assembly line with 7 operations including parallel presses) | N4: Resolved | P4: Triage | Q4: No discussion needed | R4: R2 generic, R1 specific as reported; not used for coding
A5: D004 | B5: S1 – Schmitt et al. (2026) | C5: strategic_planning_scope | D5: strategic_planning_scope.vdi5200_phase Type: list[VDI5200Phase] VDI 5200 factory planning phase(s) the method supports, pick all applicable. 'NA' (exclusive) iff 'factory-planning' is not in subdomain. Types: - 1-setting-of-objectives: Phase 1: Zielfestlegung (setting of objectives) - 2-project-basis: Phase 2: Grundlagenermittlung (establishment of the project basis) - 3-concept-planning: Phase 3: Konzeptplanung (concept planning: structure, dimensioning, layout variants) - 4-detailed-planning: Phase 4: Detailplanung (detailed planning) - 5-preparation-for-realization: Phase 5: Realisierungsvorbereitung (preparation for realization, tenders) - 6-realization-supervision: Phase 6: Realisierungsueberwachung (realization supervision) - 7-ramp-up-support: Phase 7: Hochlaufbetreuung (ramp-up support) - NA: Not a factory planning study | E5: multi-select | F5: High | G5: Only R1: 4-detailed-planning | H5: 3-concept-planning; 4-detailed-planning | I5: 3-concept-planning | J5: VDI 5200 is not referenced. The method evaluates line variants via simulation: structural changes such as adding a parallel station, and buffer dimensioning (Sec. 4.3.3). This fits concept-planning dimensioning and variant evaluation as well as detailed-planning parameter refinement. The mapping is uncertain (?) because the study concerns improvement of existing lines rather than a new factory planning project. Implementation in production is explicitly out of scope (Fig. 1 caption). | K5: The method supports evaluating different configurations (e.g., buffer sizes, parallel stations) to determine the best improvement. This is a conceptual evaluation of system variants, aligning with VDI 5200 Phase 3 (Konzeptplanung). It is not Phase 4 (Detailplanung) as it doesn't produce detailed engineering drawings or specific component specs, nor Phase 1/2 as the objectives and basis are already defined by the case studies. | L5: 3-concept-planning; 4-detailed-planning | N5: Resolved | Q5: Resolved by reviewers
A6: D005 | B6: S1 – Schmitt et al. (2026) | C6: strategic_planning_scope | D6: strategic_planning_scope.planning_horizon_tiers Type: list[PlanningHorizonTier] Reviewer-judged planning horizon tiers for which the paper's method produces or supports a decision, pick all applicable; tiers only mentioned as context do not count. 'NA' only if no tier is addressed. Strategic is selected iff system_configuring_decision is true. Types: - NA: No planning horizon addressed - Strategic: Strategic planning horizon (system configuration: what exists); set iff system_configuring_decision - Tactical: Tactical planning horizon (mid-term allocation of existing resources) - Operational: Operational planning horizon (short-term scheduling and control) | E6: multi-select | F6: High | G6: Only R1: Tactical | H6: Strategic; Tactical | I6: Strategic | J6: No horizon statements appear in the paper; the tiers are reviewer judgement. Strategic: structural changes determine what exists, e.g. 'Add a third parallel press with its own pre-buffer instance' (Fig. 14) and buffer capacity increases (Fig. 7, 14). Tactical: parametric improvements of existing machines, such as availability, cycle time, MTTR and defect rate (Table 5, Table 7). The strategic tier is borderline (?) because the decisions concern line-level modification within an existing plant. | K6: The method supports decisions that configure the system structure, such as adding or removing operations (structural adaptations) and changing buffer capacities. According to the schema definition, 'Strategic' is selected iff system_configuring_decision is true. These decisions determine what exists in the system (e.g., number of parallel presses), which is a system configuration decision. | L6: Strategic; Tactical | N6: Resolved | Q6: Resolved by reviewers
A7: D006 | B7: S1 – Schmitt et al. (2026) | C7: strategic_planning_scope | D7: strategic_planning_scope.authors_claimed_tier Type: list[PlanningHorizonTier] Tier(s) the authors themselves claim to address (e.g., 'strategic planning'), regardless of the reviewer judgement in planning_horizon_tiers; 'NA' if the authors make no tier claim. Compared with planning_horizon_tiers in the analysis ('claimed strategic, actually tactical'). Types: - NA: No planning horizon addressed - Strategic: Strategic planning horizon (system configuration: what exists); set iff system_configuring_decision - Tactical: Tactical planning horizon (mid-term allocation of existing resources) - Operational: Operational planning horizon (short-term scheduling and control) | E7: categorical | F7: High | G7: Only R2: Strategic | I7: Strategic | J7: No claim found. The authors speak of 'decision support', 'process improvements' and 'scenario exploration' but do not label the work strategic, tactical or operational. | K7: The authors frame the work as supporting 'decision support' for 'process improvements' and 'capacity and energy efficiency assessments' (Abstract, Section 1). They discuss 'brownfield' cases and 'conceptual greenfield models' (Section 6.3), implying a focus on optimizing existing or near-term configurations. While they don't explicitly use the word 'strategic', the nature of the tasks (structural changes like adding machines) aligns with the strategic tier of system configuration in the context of the schema's definitions. | N7: Resolved | Q7: Resolved by reviewers
A8: D007 | B8: S1 – Schmitt et al. (2026) | C8: strategic_planning_scope | D8: strategic_planning_scope.system_configuring_decision_stated Type: bool True only if the authors themselves frame the decision as configuring or designing the system (what exists); a verbatim quote is required in the reasoning. Default False if no such statement exists. Can only be true if system_configuring_decision is true. | E8: boolean | F8: High | G8: R1 FALSE vs R2 TRUE | H8: FALSE | I8: TRUE | J8: No statement found that frames the decision as designing or configuring the system. The authors describe 'adaptations' of simulation models and 'process improvements' (Sec. 4.3.3) for 'decision support'. | K8: Section 4.3.3 states: 'Adaptations fall into one of three 'complexity' levels; ... (ii) intermediate complexity for structural adaptations (e.g., adding or removing operations)'. Section 5.4.3 describes implementing a suggestion to 'Add a third parallel press'. This explicitly frames the decision as configuring the system structure. | L8: FALSE | N8: Resolved | Q8: Resolved by reviewers
A9: D008 | B9: S1 – Schmitt et al. (2026) | C9: strategic_planning_scope | D9: strategic_planning_scope.system_configuring_decision_description Type: str | None Free-text description, if system_configuring_decision is true, of what the decision determines (entities created, capacities set, locations chosen), as reported. | E9: free-text | F9: Medium | G9: Text differs (similarity 3%) | H9: Evaluation of line modifications: adding a third parallel press with a pre-buffer (Case B) and changing buffer capacities around bottlenecks (Cases A and B), assessed on throughput, WIP and specific energy consumption. | I9: The decision determines the structural configuration of the production line, including the number of parallel machines (e.g., adding a third press), buffer capacities, and machine availability settings. | L9: Evaluation of line modifications: adding a third parallel press with a pre-buffer (Case B) and changing buffer capacities around bottlenecks (Cases A and B), assessed on throughput, WIP and specific energy consumption. | N9: Resolved | P9: Triage | Q9: Moot – follows resolved field | R9: system-configuring not stated (= R1); R2 wording frames it as stated (D007)
A10: D009 | B10: S1 – Schmitt et al. (2026) | C10: llm_intervention | D10: llm_intervention.intervention_description Type: str Free-text description of the role the LLM/agent system plays in the planning task: inputs, outputs, and decision support function as reported. | E10: free-text | F10: Medium | G10: Text differs (similarity 2%) | H10: An end-to-end LLM-driven workflow, implemented with Python scripts and several fixed LLM API calls, automates discrete-event simulation (DES) modeling for capacity and energy-efficiency assessment of manufacturing lines. Input data (MES event logs, power ratings, defects, critical process definitions (CPDs), production calendar) are first pre-processed with static Python code and PM4Py, without an LLM. The LLM roles are: - Builder-agent (GPT-5.1): adapts a generic SimPy blueprint model into an executable current-state Python simulation model, using the structured production parameters and natural-language instructions. - Inspector-agent: verifies and repairs the generated code. - Visualizer-agent (GPT-5-mini): translates the Python model into Mermaid/JavaScript flow charts for visual inspection. - Bottleneck-agent (GPT-4o, structured JSON output): turns the utilization-based bottleneck ranking into improvement suggestions. - CPD-agent (GPT-5-mini): checks the suggestions against CPD constraints and issues warnings. - Adaptor-agent (GPT-5-mini, one instance per suggestion): produces N adapted models, each checked and repaired by the inspector-agent. - Evaluator-agent (GPT-5-mini): compares the KPIs (throughput, WIP, specific energy consumption) of the baseline and adapted models and writes textual decision-support recommendations with trade-offs. Human-in-the-loop checkpoints are: mandatory inspection and repair of the initial model, an optional extra improvement suggestion, and mandatory verification of the results. The workflow was evaluated over 21 runs on two real automotive production lines (Case A: 10 runs; Case B: 11 runs). Validation compared outputs against FACTS Analyzer models. | I10: The LLM system automates the end-to-end workflow of discrete-event simulation (DES) modeling in manufacturing. It generates executable Python simulation code (using SimPy) from heterogeneous production data (event logs, machine metrics, part-flow logic) and a blueprint model. It then adapts these models based on bottleneck analysis and human suggestions, checks for constraint violations (CPDs), and evaluates simulation outcomes (Throughput, WIP, SEC) to provide decision support. The workflow involves multiple specialized LLM roles (builder, inspector, visualizer, bottleneck, CPD, adaptor, evaluator) operating in a fixed pipeline with human-in-the-loop checkpoints. | L10: An end-to-end LLM-driven workflow, implemented with Python scripts and several fixed LLM API calls, automates discrete-event simulation (DES) modeling for capacity and energy-efficiency assessment of manufacturing lines. Input data (MES event logs, power ratings, defects, critical process definitions (CPDs), production calendar) are first pre-processed with static Python code and PM4Py, without an LLM. The LLM roles are:- Builder-agent (GPT-5.1): adapts a generic SimPy blueprint model into an executable current-state Python simulation model, using the structured production parameters and natural-language instructions.- Inspector-agent: verifies and repairs the generated code.- Visualizer-agent (GPT-5-mini): translates the Python model into Mermaid/JavaScript flow charts for visual inspection.- Bottleneck-agent (GPT-4o, structured JSON output): turns the utilization-based bottleneck ranking into improvement suggestions.- CPD-agent (GPT-5-mini): checks the suggestions against CPD constraints and issues warnings.- Adaptor-agent (GPT-5-mini, one instance per suggestion): produces N adapted models, each checked and repaired by the inspector-agent.- Evaluator-agent (GPT-5-mini): compares the KPIs (throughput, WIP, specific energy consumption) of the baseline and adapted models and writes textual decision-support recommendations with trade-offs.Human-in-the-loop checkpoints are: mandatory inspection and repair of the initial model, an optional extra improvement suggestion, and mandatory verification of the results. The workflow was evaluated over 21 runs on two real automotive production lines (Case A: 10 runs; Case B: 11 runs). Validation compared outputs against FACTS Analyzer models. | N10: Resolved | P10: Triage | Q10: No discussion needed | R10: paraphrases of the same content; narrative field, no categorical impact
A11: D010 | B11: S1 – Schmitt et al. (2026) | C11: llm_intervention | D11: llm_intervention.model_usage_context Type: str | None Free-text elaboration of which model is used for what, when multiple models are reported. | E11: free-text | F11: Medium | G11: Text differs (similarity 5%) | H11: GPT-5.1 handles the most demanding tasks: model generation (builder-agent) and the inspector-agent for the initial model. GPT-5-mini handles the cost-efficient tasks: flow-chart conversion (visualizer-agent), model adaptations (adaptor-agent and inspector-agent), CPD checking and the evaluation summaries (evaluator-agent). GPT-4o generates the JSON improvement instructions from the bottleneck analysis (bottleneck-agent) because it supports structured output. | I11: GPT-5.1 is used for the most complex tasks, specifically generating the initial simulation model (builder-agent) and inspecting/repairing it (inspector-agent). GPT-5-mini is used for simpler tasks such as converting models to flow charts (visualizer-agent), implementing adaptations (adaptor-agent), and generating summaries (evaluator-agent, CPD-agent). GPT-4o is used for generating JSON instructions from bottleneck analysis (bottleneck-agent) due to its structured output capability. | L11: GPT-5.1 handles the most demanding tasks: model generation (builder-agent) and the inspector-agent for the initial model. GPT-5-mini handles the cost-efficient tasks: flow-chart conversion (visualizer-agent), model adaptations (adaptor-agent and inspector-agent), CPD checking and the evaluation summaries (evaluator-agent). GPT-4o generates the JSON improvement instructions from the bottleneck analysis (bottleneck-agent) because it supports structured output. | N11: Resolved | P11: Triage | Q11: No discussion needed | R11: paraphrases of the same content; narrative field, no categorical impact
A12: D011 | B12: S1 – Schmitt et al. (2026) | C12: evaluation_and_outcomes | D12: evaluation_and_outcomes.evaluation_paradigm Type: EvaluationParadigm Artificial vs. naturalistic evaluation (FEDS); 'NA' iff study_design is 'none'. Types: - artificial: All evaluation episodes are artificial - naturalistic: All evaluation episodes are naturalistic - both: Both artificial and naturalistic episodes - NA: No evaluation (study_design is 'none') | E12: categorical | F12: High | G12: Only R1: both | Only R2: naturalistic | H12: both | I12: naturalistic | J12: Classification is uncertain ('?'). Case A uses real MES event logs from a real production line, with power estimated from supplier specifications (Sec. 4.2), which leans naturalistic. Case B uses a simplified mock-up event log and part-flow logic so the data could be shared. The CPDs for both cases were fictitious and created with a company simulation expert (Sec. 4.2), which is artificial. All runs were executed by the authors rather than by real end users in operations, which also pushes toward artificial. Coded 'both' to reflect real-system data (Case A) alongside mock-up/fictitious inputs (Case B, CPDs). | K12: The evaluation uses 'real-world production lines' and 'heterogeneous production data' from a 'large Swedish automotive manufacturer' (Abstract, Section 4.2). The cases are described as actual production scenarios, not simulated or invented data for the purpose of the test itself (though the simulation models are built from this data). This aligns with the 'naturalistic' paradigm (real users, real problem, real organisation/system). | L12: both | N12: Resolved | Q12: Resolved by reviewers
A13: D012 | B13: S1 – Schmitt et al. (2026) | C13: evaluation_and_outcomes | D13: evaluation_and_outcomes.dataset_or_benchmark Type: str Dataset or benchmark name and size as reported. NR if absent. | E13: free-text | F13: Medium | G13: Text differs (similarity 2%) | H13: Two industrial case datasets from a Swedish automotive manufacturer: Case A (MES event logs for a 4-machine serial machining line) and Case B (simplified mock-up event log for a 7-station assembly line with parallel presses; shared on GitHub) | I13: NR | J13: Sec. 4.2 and Sec. 5.3.1/5.4.1 describe the data sources. No public benchmark was used. Case B data is available at github.com/thomasschmitt1993/LLM-DES-Modeling. Table 2 SWE-bench values are cited only to motivate model selection; they are not used to evaluate this method. | K13: The paper uses proprietary industrial data from Scania CV AB (event logs, MES data) for two specific production lines. It does not reference a public dataset or benchmark name (e.g., SWE-bench is mentioned only for LLM capability comparison in Table 2, not as the evaluation dataset for the simulation workflow). The data is described as 'heterogeneous production data' and 'event logs' but not named as a specific public benchmark. | L13: Two industrial case datasets from a Swedish automotive manufacturer: Case A (MES event logs for a 4-machine serial machining line) and Case B (simplified mock-up event log for a 7-station assembly line with parallel presses; shared on GitHub) | N13: Resolved | P13: Triage | Q13: Moot – follows resolved field | R13: evaluation_framework_type consensus includes custom-test-set → "NR" contradicts it
A14: D013 | B14: S1 – Schmitt et al. (2026) | C14: record | D14: n_reported_metrics Number of reported metrics (one row each on the reported_metrics sheet). | E14: categorical | F14: High | G14: Only R1: 15 | Only R2: 12 | H14: 15 | I14: 12 | J14: Values are taken from Tables 5, 7, 8 and 9, Figs. 6, 9, 13, 16 and 18, and Secs. 5.3 to 5.6. The SEC percentage labels in the figure transcriptions are partly inconsistent (e.g., V2 Case B SEC shown as -5.4% and -6.4%, while the evaluator text states ~6.3%), so that SEC value is omitted. The Fig. 18 percentages were read from the bar chart. | K14: Metrics were extracted from Section 5.6 (validation deviations), Table 5 and Table 7 captions (cost, time, tokens). The paper reports KPIs (TH, WIP, SEC) for the simulation models themselves (e.g., Fig 6, Fig 13), but the primary evaluation metrics for the *method's* performance are the deviations from the ground truth (FACTS Analyzer) and the efficiency metrics (cost/time). The KPI values of the simulation models are outputs of the simulation, not metrics of the LLM framework's accuracy per se, though they are reported. I included the deviation metrics as they directly evaluate the LLM's output quality against a comparator. | L14: 15 | N14: Resolved | Q14: Resolved by reviewers
A15: D014 | B15: S1 – Schmitt et al. (2026) | C15: evaluation_and_outcomes | D15: evaluation_and_outcomes.sample_size Type: str Number of test cases, users, or records as reported. NR if absent. | E15: free-text | F15: Medium | G15: Text differs (similarity 78%) | H15: 2 production cases; 21 experimental workflow runs (10 for Case A, 11 for Case B) | I15: 21 experimental runs (10 for Case A, 11 for Case B) | J15: Stated in the abstract and in Sec. 5 and 5.5. Simulation replications (25 for Case A, 10 for Case B) are a separate quantity and refer to stochastic simulation runs, not LLM evaluation items. | K15: The Abstract states '21 experimental runs'. Section 5.3.4 mentions 'ten experiments' for Case A. Section 5.4.4 mentions 'eleven experiments' for Case B. 10 + 11 = 21. | L15: 2 production cases; 21 experimental workflow runs (10 for Case A, 11 for Case B) | N15: Resolved | P15: Triage | Q15: No discussion needed | R15: R1 contains all R2 counts (superset)
A16: D015 | B16: S1 – Schmitt et al. (2026) | C16: evaluation_and_outcomes | D16: evaluation_and_outcomes.repeated_runs Type: Annotated[int, FieldInfo(annotation=NoneType, required=True, metadata=[Ge(ge=1)])] | Literal['NR'] Number of repeated runs per test item/case used to capture LLM output variability (1 if explicitly a single run). NR if not reported. | E16: categorical | F16: High | G16: Only R1: 10 | Only R2: 21 | H16: 10 | I16: 21 | J16: Repeated runs: the full LLM workflow was executed 10 times on Case A and 11 times on Case B to capture output variability (Tables 5 and 7). The minimum of 10 is coded because the schema requires a single integer. LLM-as-judge: the inspector and evaluator agents are components of the method itself; the method's outputs were judged by the authors and the human-in-the-loop, not by an LLM. Efficiency: tokens, API cost and execution time are reported (Table 5 and 7 captions). Statistical testing: input-output validation against FACTS Analyzer used means and 95% confidence intervals from independent replications (Sec. 4.4, 5.6). No hypothesis tests were reported. | K16: Repeated runs: 21 total runs across two cases. LLM as judge: The 'evaluator-agent' interprets results, but the *evaluation of the framework's validity* is done by comparing against FACTS Analyzer (conventional method) and human inspection, not by an LLM scoring the LLM's performance against a ground truth in a meta-evaluation sense. However, the 'evaluator-agent' is part of the workflow. The schema asks if an LLM scores/judges the *outputs of the paper's method*. The paper's method *is* the workflow. The evaluation of the workflow's success is based on code correctness (human/inspector agent) and KPI deviation (comparison to FACTS). The 'evaluator-agent' is a component of the system being tested, not an external judge of the system's validity. Therefore, false. Efficiency: True, cost and time are reported in Table 5/7 captions. Statistical testing: True, Section 5.6 mentions '95% confidence intervals' and 'statistical testing' is suggested in the evaluator output (Fig 10/17) and validation criteria mention confidence intervals. | L16: 10 for Case A, 11 for Case B | N16: Resolved | O16: should be free-text answer because reference to test case is needed | P16: R1+R2 | Q16: Re-coded v0.10.0 | R16: v0.10.0: free text (D015); per-case counts as reported in Tables 5 and 7
A17: D016 | B17: S1 – Schmitt et al. (2026) | C17: evaluation_and_outcomes | D17: evaluation_and_outcomes.reported_limitations Type: list[str] 1-3 sentence paraphrase of author-stated limitations. Empty list if none are stated (= NR). | E17: free-text | F17: Medium | G17: Text differs (similarity 19%) | H17: The tested cases were relatively simple (a serial line and a line with one parallel station), so generalizability to complex systems with multiple variants and interdependent flows remains unvalidated.; Output consistency and reproducibility are limited: model generation was error-prone, especially structural split/merge errors in Case B, and required human checks and manual corrections.; Whether the approach reduces overall modeling time was not assessed, and there was no comparison against manual modeling or established ASMG approaches.; Multi-agent configurations and hyperparameter sensitivity (e.g., temperature) were not systematically evaluated; default API parameters were used.; Generating C++/XML code for commercial tools such as FACTS Analyzer performed poorly in early experiments, likely due to training-data bias toward Python.; Input data ingestion was partly manual (buffer capacities, process logic), and the CPDs and Case B data were fictitious or simplified mock-ups. | I17: Output consistency and generalizability to more complex manufacturing systems remain challenges.; The cases tested were relatively simple (sequential or simple parallel), and generalizability to complex part flows and multiple variants is unvalidated.; Certain input data (buffer capacities, process logic) had to be added manually, limiting full automation of data ingestion. | J17: Drawn from Sec. 6.4 (Limitations and future research), the Conclusion, and Sec. 4.2 for the mock-up and fictitious data. | K17: Section 6.4 ('Limitations and future research') explicitly states: 'the generalizability of the proposed approach to more complex production scenarios remains to be validated', 'certain information... had to be added manually', and 'limitations in output consistency were observed'. The Abstract also mentions 'current limitations of LLM-driven simulation, particularly regarding output consistency and generalizability.' | L17: The tested cases were relatively simple (a serial line and a line with one parallel station), so generalizability to complex systems with multiple variants and interdependent flows remains unvalidated.; Output consistency and reproducibility are limited: model generation was error-prone, especially structural split/merge errors in Case B, and required human checks and manual corrections.; Whether the approach reduces overall modeling time was not assessed, and there was no comparison against manual modeling or established ASMG approaches.; Multi-agent configurations and hyperparameter sensitivity (e.g., temperature) were not systematically evaluated; default API parameters were used.; Generating C++/XML code for commercial tools such as FACTS Analyzer performed poorly in early experiments, likely due to training-data bias toward Python.; Input data ingestion was partly manual (buffer capacities, process logic), and the CPDs and Case B data were fictitious or simplified mock-ups.; Output consistency and generalizability to more complex manufacturing systems remain challenges.; The cases tested were relatively simple (sequential or simple parallel), and generalizability to complex part flows and multiple variants is unvalidated.; Certain input data (buffer capacities, process logic) had to be added manually, limiting full automation of data ingestion. | N17: Resolved | P17: Triage | Q17: No discussion needed | R17: different limitation items → union kept for Tier-3 thematic coding
A18: D017 | B18: S1 – Schmitt et al. (2026) | C18: evaluation_and_outcomes | D18: evaluation_and_outcomes.outcome_summary Type: str | None Free-text narrative summary of the main results beyond isolated metrics, as reported. | E18: free-text | F18: Medium | G18: Text differs (similarity 3%) | H18: Across 21 runs on two industrial cases, the LLM workflow (GPT-5.1 builder/inspector, GPT-5-mini adaptor/visualizer/CPD/evaluator, GPT-4o bottleneck agent, with a SimPy blueprint for one-shot generation) generated executable DES models. It also proposed and implemented bottleneck-based adaptations, flagged CPD violations, and produced trade-off evaluations. Model generation was the weakest stage: 80% correct for Case A and 64% for Case B, with one crash and five manual corrections, mostly structural errors in parallel routing. Adaptation (92-97%) and evaluation (100%) were reliable. Validation against manually built FACTS Analyzer models showed deviations within the 5-10% threshold: about 4% for Case A and below 1% for Case B. Costs were about $0.13-0.16 per run and run times about 10-20 minutes. The authors conclude that the hybrid human-in-the-loop approach is feasible but limited by consistency and generalizability. | I18: The LLM-driven workflow successfully generated, adapted, and evaluated discrete-event simulation models for two manufacturing cases. The generated models showed high accuracy compared to commercial simulation software (deviations <10%, mostly <5%). The workflow demonstrated the ability to identify bottlenecks, propose improvements, check constraints, and evaluate trade-offs. However, errors occurred in model generation (especially for complex parallel structures) requiring human correction, and output consistency varied across runs. | L18: Across 21 runs on two industrial cases, the LLM workflow (GPT-5.1 builder/inspector, GPT-5-mini adaptor/visualizer/CPD/evaluator, GPT-4o bottleneck agent, with a SimPy blueprint for one-shot generation) generated executable DES models. It also proposed and implemented bottleneck-based adaptations, flagged CPD violations, and produced trade-off evaluations. Model generation was the weakest stage: 80% correct for Case A and 64% for Case B, with one crash and five manual corrections, mostly structural errors in parallel routing. Adaptation (92-97%) and evaluation (100%) were reliable. Validation against manually built FACTS Analyzer models showed deviations within the 5-10% threshold: about 4% for Case A and below 1% for Case B. Costs were about $0.13-0.16 per run and run times about 10-20 minutes. The authors conclude that the hybrid human-in-the-loop approach is feasible but limited by consistency and generalizability. | N18: Resolved | P18: Triage | Q18: No discussion needed | R18: paraphrases of the same content; narrative field, no categorical impact
A19: D018 | B19: S1 – Schmitt et al. (2026) | C19: gap_indicators | D19: gap_indicators.hitl_description Type: str | None Free-text elaboration of how the HITL pattern operates in the system, as reported. | E19: free-text | F19: Medium | G19: Text differs (similarity 21%) | H19: There are three human checkpoints. (1) Mandatory inspection and repair of the LLM-generated baseline SimPy model after the inspector-agent's check and before execution. (2) An optional step in which the operator adds an extra improvement suggestion via terminal text input, alongside the bottleneck-agent's suggestions. The operator also reviews the CPD-agent's warnings and the context-specific constraints that the LLM cannot see, such as layout, space and cost. (3) A mandatory check of the evaluator-agent's interpretation of the results, to catch hallucinations before decision support is given. | I19: The framework integrates human oversight at three key stages: (1) Mandatory inspection and repair of the generated initial simulation model; (2) Optional addition of manual improvement suggestions to the list generated by the LLM; (3) Mandatory verification of the final evaluation results and trade-offs before decision support. | L19: There are three human checkpoints.(1) Mandatory inspection and repair of the LLM-generated baseline SimPy model after the inspector-agent's check and before execution.(2) An optional step in which the operator adds an extra improvement suggestion via terminal text input, alongside the bottleneck-agent's suggestions. The operator also reviews the CPD-agent's warnings and the context-specific constraints that the LLM cannot see, such as layout, space and cost.(3) A mandatory check of the evaluator-agent's interpretation of the results, to catch hallucinations before decision support is given. | N19: Resolved | P19: Triage | Q19: No discussion needed | R19: paraphrases of the same content; narrative field, no categorical impact
A20: D019 | B20: S1 – Schmitt et al. (2026) | C20: gap_indicators | D20: gap_indicators.domain_knowledge_type Type: Annotated[list[DomainKnowledgeType], AfterValidator(func=<function <lambda> at 0x7ff41b44c670>)] | None All types of domain knowledge formalization present, required if domain_knowledge_formalization_present is true. Types: - ontology: Formal ontology: classes, relations and axioms of the domain (e.g., OWL), schema level - knowledge-graph: Knowledge graph: domain instances and their relations stored as a graph - standards-encoding: Machine-readable encoding of domain standards (e.g., VDI 5200, ISA-95, ISO 22400) - structured-schema: Non-graph metamodel or schema (e.g., JSON Schema, UML) for domain entities and constraints - relational-database: Relational database or taxonomy of domain entities and attributes - code-template: Code or model template encoding domain structure (e.g., simulation blueprint) - mathematical-model: Optimization or simulation model encoding domain structure and rules - other: Other domain knowledge formalization (specify) | E20: multi-select | F20: High | G20: Only R1: mathematical-model | H20: code-template; mathematical-model | I20: code-template | J20: code-template: the SimPy blueprint template is adapted by the builder-agent (Sec. 5.1, Appendix A). mathematical-model: DES models encoding machine performance, buffers and schedules are executed to compute TH, WIP and SEC (Sec. 4.3.2). This tag is less certain (?), since the model is itself the output generated from the template. | K20: The primary formalization is the 'blueprint model' described in Section 5.1 and Appendix A. It is a Python code template using SimPy that defines the structure of machines, buffers, and logic. This fits the definition of 'code-template: Code or model template encoding domain structure (e.g., simulation blueprint)'. While CPDs are mentioned, they are provided as text instructions rather than a formal ontology or KG. | L20: code-template; mathematical-model | N20: Resolved | Q20: Resolved by reviewers
A21: D020 | B21: S1 – Schmitt et al. (2026) | C21: gap_indicators | D21: gap_indicators.domain_knowledge_description Type: str | None Free-text elaboration of what domain knowledge is formalized and how, as reported. | E21: free-text | F21: Medium | G21: Text differs (similarity 5%) | H21: The generic SimPy blueprint contains functions for: - production schedules - merger and splitter processes at parallel stations - part generation and movement - DelayBuffer and Machine classes with availability, MTTR, power ratings and defect rates - exponential failure distributions - KPI calculation It serves as a one-shot example. Structured parameter tables derived from MES event logs, with part flow obtained via PM4Py process mining, are also inserted into the prompts. | I21: The system uses a Python-based 'blueprint model' (SimPy code) that serves as a one-shot example for the LLM. This template encodes the standard structure for discrete-event simulation in manufacturing, including machine classes, buffer definitions, part generation logic, and KPI calculation methods. It ensures the generated code follows a consistent, executable pattern. | L21: The generic SimPy blueprint contains functions for:- production schedules- merger and splitter processes at parallel stations- part generation and movement- DelayBuffer and Machine classes with availability, MTTR, power ratings and defect rates- exponential failure distributions- KPI calculationIt serves as a one-shot example. Structured parameter tables derived from MES event logs, with part flow obtained via PM4Py process mining, are also inserted into the prompts. | N21: Resolved | P21: Triage | Q21: Moot – follows resolved field | R21: description follows consensus type (= R1) (D019)
A22: D021 | B22: S1 – Schmitt et al. (2026) | C22: gap_indicators | D22: gap_indicators.evaluation_framework_type Type: Annotated[list[EvaluationFrameworkType], AfterValidator(func=<function <lambda> at 0x7ff41b44c670>)] | None All framework elements used, required if evaluation_framework_used is true. Code both the test instrument (benchmark, custom test set, expert ground truth) and the scoring (rubric, domain-specific metric). Types: - benchmark: Public, standardised benchmark reused from prior work - custom-test-set: Test items or cases built by the authors for this paper - expert-ground-truth: Outputs compared with expert or practitioner decisions - rubric: Graded scoring scale or criteria (incl. Likert ratings, ordinal suitability levels) - domain-specific-metric: Metric defined by the planning domain (e.g., throughput, space utilisation, cost); not generic accuracy/F1 - other: Other evaluation framework (specify) | E22: multi-select | F22: High | G22: Only R1: custom-test-set | H22: custom-test-set; expert-ground-truth; domain-specific-metric | I22: expert-ground-truth; domain-specific-metric | J22: custom-test-set: two industrial case studies were built by the authors and run repeatedly. expert-ground-truth: LLM-generated models are compared with expert-built FACTS Analyzer reference models, and the workflow was validated with a company simulation expert (Sec. 4.4). domain-specific-metric: throughput, WIP and SEC deviations are used as metrics (Tables 8 and 9). | K22: 1. 'expert-ground-truth': Section 5.6 states: 'Validation included the comparison of the results of the generated models against equivalent models built in FACTS Analyzer simulation software.' These manually built models serve as the ground truth. 2. 'domain-specific-metric': The evaluation uses manufacturing-specific KPIs: 'Throughput (TH)', 'Work-in-process (WIP)', and 'Specific Energy Consumption (SEC)' (Section 4.2). | L22: custom-test-set; expert-ground-truth; domain-specific-metric | N22: Resolved | Q22: Resolved by reviewers
A23: D022 | B23: S1 – Schmitt et al. (2026) | C23: gap_indicators | D23: gap_indicators.evaluation_framework_description Type: str | None Free-text elaboration of the evaluation framework and its application, as reported. | E23: free-text | F23: Medium | G23: Text differs (similarity 3%) | H23: Ten runs were performed for Case A (4-station serial machining line) and eleven for Case B (7-station assembly line with parallel presses). For each run, the authors recorded: - model generation success, manual correction or failure, and the error type (structural, parametric, scheduling) - correctness of BT suggestions and CPD flagging - success of the adaptations - correctness of the evaluator interpretation Accuracy per stage is summarized in Fig. 18: generation 80% and 64%, adaptation 92% and 97%, evaluation 100% for Case A and Case B respectively. Tokens, cost and execution time were also reported. Input-output validation compared the first run of each case with FACTS Analyzer models. Deviations were within 10%: about -4% TH and about 4% WIP for Case A, and under 1% for Case B. | I23: The evaluation involves running the LLM-generated simulation models and comparing their Key Performance Indicators (Throughput, WIP, SEC) against manually built models in commercial software (FACTS Analyzer). The comparison uses means and 95% confidence intervals over multiple replications. A model is considered valid if deviations are within a 5-10% threshold and no systematic bias is detected. Additionally, code correctness and LLM accuracy (hallucinations, logic errors) are tracked across 21 experimental runs. | L23: Ten runs were performed for Case A (4-station serial machining line) and eleven for Case B (7-station assembly line with parallel presses). For each run, the authors recorded:- model generation success, manual correction or failure, and the error type (structural, parametric, scheduling)- correctness of BT suggestions and CPD flagging- success of the adaptations- correctness of the evaluator interpretationAccuracy per stage is summarized in Fig. 18: generation 80% and 64%, adaptation 92% and 97%, evaluation 100% for Case A and Case B respectively. Tokens, cost and execution time were also reported.Input-output validation compared the first run of each case with FACTS Analyzer models. Deviations were within 10%: about -4% TH and about 4% WIP for Case A, and under 1% for Case B. | N23: Resolved | P23: Triage | Q23: Moot – follows resolved field | R23: description follows consensus type (= R1) (D021)
A24: D023 | B24: S1 – Schmitt et al. (2026) | C24: quality_appraisal | D24: quality_appraisal.q4_positioning_against_prior_work Type: AppraisalAnswer Q4: Is the contribution compared against existing solutions with explicit differentiation? Types: - Yes: Criterion fully met - Partially: Criterion partly met - No: Criterion not met | E24: categorical | F24: High | G24: Only R1: Partially | Only R2: Yes | H24: Partially | I24: Yes | J24: Sec. 3 reviews ASMG approaches and LLM-simulation work (Jackson et al., Obinwanne & Feng, Dengler et al., Giabbanelli et al.). It differentiates the contribution as the first end-to-end workflow with structured data inputs (Sec. 6: 'no studies have demonstrated and validated a complete end-to-end workflow'). However, there is no empirical comparison against existing ASMG or LLM approaches, which the authors themselves list as future work. | K24: Section 3 (Related Works) reviews prior work on simulation automation and LLMs in manufacturing. It specifically cites studies like Jackson et al. [4] and Obinwanne and Feng [35] that demonstrated LLMs for simple DES generation, and explicitly states that this study addresses the gap by presenting a 'complete end-to-end workflow spanning model generation, adaptation, and evaluation' which prior studies had not demonstrated and validated. Section 6.1 further contrasts this work with earlier proof-of-concepts. | L24: Partially | N24: Resolved | Q24: Resolved by reviewers
